Workbook

Sheet README
A1: Pesticide Club Shop: database design
A2: Copied from the ERD agreed in chat. Tables marked Proposed were listed but not drawn, and their columns are suggestions.
A4: Sheet | B4: What it holds
A5: Tables | B5: All tables with group, purpose, type, status and a live column count
A6: Columns | B6: Every column with type, key, foreign key target and notes
A7: Relationships | B7: Parent and child tables with the foreign key column
A8: Common columns | B8: Columns added to every table for sync and multi-branch
A9: Decisions | B9: Your answers and what each one does to the schema
A10: Open questions | B10: Questions for the owner. Type his answers in the yellow cells
A12: Totals
A13: Tables | B13: =COUNTA(Tables!A2:A28) -> 27
A14: Tables in the ERD | B14: =COUNTIF(Tables!F2:F28,"In ERD") -> 18
A15: Proposed tables | B15: =COUNTIF(Tables!F2:F28,"Proposed*") -> 9
A16: Columns listed | B16: =COUNTA(Columns!B2:B500) -> 182
A17: Foreign keys | B17: =COUNTIF(Columns!D2:D500,"FK") -> 26
A18: Relationships | B18: =COUNTA(Relationships!A2:A200) -> 23
A20: Conventions
A21: Primary keys are UUIDs stored as text.
A22: Money is stored as whole numbers in paisa. Never decimals or floats.
A23: Quantities are whole numbers in the base unit (ml, g or piece).
A24: Prices are per pack. A loose line total is rounded once per invoice line.
A25: Timestamps are UTC ISO text, shown in local time.
A26: Stock and balances are never stored. They are sums of stock_movements and ledger_entries.
A27: Append-only tables are never edited or deleted. Mistakes become reversing rows.
A28: Transaction records (invoices, purchases, returns) are never deleted. A void or return adds new rows.

Sheet Tables
A1: Table | B1: Group | C1: Purpose | D1: Type | E1: Columns | F1: Status | G1: Notes
A2: categories | B2: Catalog | C2: Product categories | D2: Editable | E2: =COUNTIF(Columns!$A$2:$A$500,A2) -> 3 | F2: In ERD
A3: brands | B3: Catalog | C3: Product brands | D3: Editable | E3: =COUNTIF(Columns!$A$2:$A$500,A3) -> 3 | F3: In ERD
A4: products | B4: Catalog | C4: Items sold, with retail and wholesale prices, tax rate and unit setup | D4: Editable | E4: =COUNTIF(Columns!$A$2:$A$500,A4) -> 15 | F4: In ERD | G4: Prices are per pack in paisa. Loose sales use base units
A5: batches | B5: Catalog | C5: Batch number, expiry date and cost for each product delivery | D5: Editable | E5: =COUNTIF(Columns!$A$2:$A$500,A5) -> 6 | F5: In ERD | G5: Batch and expiry required on all products
A6: stock_movements | B6: Stock | C6: Every stock change as a signed quantity per batch | D6: Append-only | E6: =COUNTIF(Columns!$A$2:$A$500,A6) -> 8 | F6: In ERD | G6: Current stock = sum of qty_delta per batch. Never stored as an editable number
A7: suppliers | B7: Purchasing | C7: Companies and dealers he buys from | D7: Editable | E7: =COUNTIF(Columns!$A$2:$A$500,A7) -> 5 | F7: In ERD
A8: purchases | B8: Purchasing | C8: Purchase header from a supplier | D8: Transaction | E8: =COUNTIF(Columns!$A$2:$A$500,A8) -> 7 | F8: In ERD
A9: purchase_items | B9: Purchasing | C9: Items received on a purchase, one row per batch | D9: Transaction | E9: =COUNTIF(Columns!$A$2:$A$500,A9) -> 5 | F9: In ERD
A10: purchase_returns | B10: Purchasing | C10: Stock sent back to a supplier (case by case) | D10: Transaction | E10: =COUNTIF(Columns!$A$2:$A$500,A10) -> 6 | F10: In ERD | G10: Used only when needed
A11: purchase_return_items | B11: Purchasing | C11: Items on a supplier return | D11: Transaction | E11: =COUNTIF(Columns!$A$2:$A$500,A11) -> 5 | F11: In ERD
A12: customers | B12: People | C12: Farmers and other buyers, with credit limit | D12: Editable | E12: =COUNTIF(Columns!$A$2:$A$500,A12) -> 8 | F12: In ERD | G12: Extra farmer fields are an open question
A13: invoices | B13: Sales | C13: Sales header: retail or wholesale, due date, status active or voided | D13: Transaction | E13: =COUNTIF(Columns!$A$2:$A$500,A13) -> 14 | F13: In ERD | G13: Never deleted. A void adds reversing rows to stock and ledger
A14: invoice_items | B14: Sales | C14: One row per batch used on an invoice, with cost saved at sale time | D14: Transaction | E14: =COUNTIF(Columns!$A$2:$A$500,A14) -> 11 | F14: In ERD | G14: Discount is per item only. Tax saved per line
A15: sales_returns | B15: Sales | C15: Return linked to an original invoice, approved by the owner | D15: Transaction | E15: =COUNTIF(Columns!$A$2:$A$500,A15) -> 8 | F15: In ERD | G15: A return must link to an invoice
A16: sales_return_items | B16: Sales | C16: Returned lines pointing at the exact invoice item | D16: Transaction | E16: =COUNTIF(Columns!$A$2:$A$500,A16) -> 6 | F16: In ERD | G16: Condition decides if stock goes back as sellable
A17: payments | B17: Money | C17: Cash, bank, Easypaisa and JazzCash payments in or out | D17: Append-only | E17: =COUNTIF(Columns!$A$2:$A$500,A17) -> 8 | F17: In ERD | G17: Payments reduce the overall balance, not one invoice
A18: ledger_entries | B18: Money | C18: The Khata: signed amounts per customer or supplier | D18: Append-only | E18: =COUNTIF(Columns!$A$2:$A$500,A18) -> 8 | F18: In ERD | G18: Balance = sum of amount_delta. Opening balances go in as one row
A19: users | B19: People | C19: Owner and staff logins | D19: Editable | E19: =COUNTIF(Columns!$A$2:$A$500,A19) -> 6 | F19: In ERD | G19: Owner-only: approve returns, change prices, view profit and cost
A20: shops | B20: System | C20: The shop record | D20: Editable | E20: =COUNTIF(Columns!$A$2:$A$500,A20) -> 5 | F20: Proposed (not drawn) | G20: One shop for now
A21: branches | B21: System | C21: Branch of a shop | D21: Editable | E21: =COUNTIF(Columns!$A$2:$A$500,A21) -> 4 | F21: Proposed (not drawn) | G21: One branch for now, ready for more
A22: devices | B22: System | C22: Each PC running the app | D22: Editable | E22: =COUNTIF(Columns!$A$2:$A$500,A22) -> 4 | F22: Proposed (not drawn) | G22: Used for invoice number prefixes and sync
A23: settings | B23: System | C23: Shop name, invoice footer, near-expiry days (30), backup folders | D23: Editable | E23: =COUNTIF(Columns!$A$2:$A$500,A23) -> 3 | F23: Proposed (not drawn)
A24: number_sequences | B24: System | C24: Per-device counters for invoice and return numbers | D24: Editable | E24: =COUNTIF(Columns!$A$2:$A$500,A24) -> 5 | F24: Proposed (not drawn) | G24: Example format: INV-A-000123
A25: expenses | B25: System | C25: Shop expenses such as rent, salary, electricity | D25: Editable | E25: =COUNTIF(Columns!$A$2:$A$500,A25) -> 7 | F25: Proposed (not drawn) | G25: Built but hidden in the UI until the owner confirms
A26: audit_log | B26: System | C26: Who did what and when | D26: Append-only | E26: =COUNTIF(Columns!$A$2:$A$500,A26) -> 7 | F26: Proposed (not drawn)
A27: change_log | B27: System | C27: Every write, kept for later cloud sync | D27: Append-only | E27: =COUNTIF(Columns!$A$2:$A$500,A27) -> 7 | F27: Proposed (not drawn)
A28: backup_log | B28: System | C28: Result of each backup run | D28: Append-only | E28: =COUNTIF(Columns!$A$2:$A$500,A28) -> 8 | F28: Proposed (not drawn)

Sheet Columns
A1: Table | B1: Column | C1: Type | D1: Key | E1: References | F1: Notes
A2: categories | B2: id | C2: uuid | D2: PK
A3: categories | B3: name_en | C3: text
A4: categories | B4: name_ur | C4: text
A5: brands | B5: id | C5: uuid | D5: PK
A6: brands | B6: name_en | C6: text
A7: brands | B7: name_ur | C7: text
A8: products | B8: id | C8: uuid | D8: PK
A9: products | B9: category_id | C9: uuid | D9: FK | E9: categories.id
A10: products | B10: brand_id | C10: uuid | D10: FK | E10: brands.id
A11: products | B11: name_en | C11: text
A12: products | B12: name_ur | C12: text
A13: products | B13: sku | C13: text
A14: products | B14: barcode | C14: text | F14: Optional
A15: products | B15: base_unit | C15: text | F15: ml, g or piece
A16: products | B16: pack_size | C16: int | F16: Base units per pack
A17: products | B17: allow_loose | C17: bool
A18: products | B18: retail_price | C18: int | F18: Paisa per pack
A19: products | B19: wholesale_price | C19: int | F19: Paisa per pack
A20: products | B20: tax_rate_bp | C20: int | F20: 1800 means 18 percent
A21: products | B21: min_stock | C21: int | F21: Base units
A22: products | B22: is_active | C22: bool
A23: batches | B23: id | C23: uuid | D23: PK
A24: batches | B24: product_id | C24: uuid | D24: FK | E24: products.id
A25: batches | B25: supplier_id | C25: uuid | D25: FK | E25: suppliers.id
A26: batches | B26: batch_no | C26: text
A27: batches | B27: expiry_date | C27: date
A28: batches | B28: cost_price | C28: int | F28: Paisa per pack
A29: stock_movements | B29: id | C29: uuid | D29: PK
A30: stock_movements | B30: batch_id | C30: uuid | D30: FK | E30: batches.id
A31: stock_movements | B31: qty_delta | C31: int | F31: Base units, signed
A32: stock_movements | B32: movement_type | C32: text | F32: purchase, sale, return or adjust
A33: stock_movements | B33: ref_type | C33: text
A34: stock_movements | B34: ref_id | C34: uuid
A35: stock_movements | B35: created_by | C35: uuid | F35: User who made the movement
A36: stock_movements | B36: created_at | C36: timestamp
A37: suppliers | B37: id | C37: uuid | D37: PK
A38: suppliers | B38: name_en | C38: text
A39: suppliers | B39: name_ur | C39: text
A40: suppliers | B40: phone | C40: text
...

Sheet Relationships
A1: Parent table | B1: Child table | C1: Cardinality | D1: Foreign key column | E1: Meaning
A2: categories | B2: products | C2: 1 to many | D2: products.category_id | E2: Groups products
A3: brands | B3: products | C3: 1 to many | D3: products.brand_id | E3: Labels products
A4: products | B4: batches | C4: 1 to many | D4: batches.product_id | E4: A product has many batches
A5: suppliers | B5: batches | C5: 1 to many | D5: batches.supplier_id | E5: Supplier of a batch
A6: suppliers | B6: purchases | C6: 1 to many | D6: purchases.supplier_id | E6: Purchases from a supplier
A7: purchases | B7: purchase_items | C7: 1 to 1 or more | D7: purchase_items.purchase_id | E7: Lines on a purchase
A8: batches | B8: purchase_items | C8: 1 to many | D8: purchase_items.batch_id | E8: Batch received on a purchase line
A9: suppliers | B9: purchase_returns | C9: 1 to many | D9: purchase_returns.supplier_id | E9: Supplier takes stock back
A10: purchases | B10: purchase_returns | C10: 1 to many | D10: purchase_returns.purchase_id | E10: FK exists. Not drawn in the ERD
A11: purchase_returns | B11: purchase_return_items | C11: 1 to 1 or more | D11: purchase_return_items.purchase_return_id | E11: Lines on a supplier return
A12: batches | B12: purchase_return_items | C12: 1 to many | D12: purchase_return_items.batch_id | E12: Batch returned
... A24: customers | B24: ledger_entries | C24: 1 to many | D24: ledger_entries.party_id | E24: No database FK. party_type selects customers or suppliers

Sheet Common columns
A1: Column | B1: Type | C1: Applies to | D1: Purpose
A2: shop_id | B2: uuid | C2: Editable and append-only tables | D2: Which shop owns the row. Kept for later multi-shop use
A3: branch_id | B3: uuid | C3: Editable and append-only tables | D3: Which branch. Used for branch-aware stock later
A4: device_id | B4: uuid | C4: Editable and append-only tables | D4: Which PC created the row. Needed for sync and invoice numbers
A5: created_at | B5: timestamp | C5: Editable and append-only tables | D5: UTC ISO text
A6: updated_at | B6: timestamp | C6: Editable tables only | D6: Sync needs to know what changed since the last run
A7: deleted_at | B7: timestamp | C7: Editable tables only | D7: Soft delete flag so deletions can sync
A8: version | B8: int | C8: Editable and append-only tables | D8: Increments on each edit. Used for conflict handling in sync
A10: Transaction records (invoices, purchases, returns) follow the editable set, because their status can change on a void.

Sheet Decisions
A1: Decision | B1: Effect on the database
A2: Loose sales and sealed packs, both ways | B2: Stock is a whole number in a base unit (ml, g or piece). 1L bottle = 1000 ml. Products get base_unit, pack_size and allow_loose
A3: Batch and expiry on all products | B3: Every stock movement has a batch. Batch and expiry are required
A4: Retail and wholesale prices | B4: Two price columns per product. Each invoice records which price type was used. Customers can have a default
A5: Payments reduce the overall balance | B5: Payments go to the ledger, not to a specific invoice
A6: Credit limit and due dates | B6: customers.credit_limit and invoices.due_date
A7: Returns must link to an invoice | B7: sales_returns.invoice_id is required
A8: Supplier returns, case by case | B8: Small purchase_returns pair of tables, used when needed
A9: Owner plus staff | B9: Roles. Approve returns, change prices and view profit and cost are owner-only
A10: Thermal and A4 print layouts | B10: Both templates built on the same invoice data
A11: English and Urdu | B11: name_en and name_ur on products and customers. Urdu fonts, right-to-left printing, search in both
A12: 20 to 50 invoices a day | B12: SQLite handles this easily. No tuning needed
... A20: Fresh start, no Django import | B20: No data migration from the old version

Sheet Open questions
A1: Type the owner's answer in the yellow Answer column. Row 3 is an example only and can be deleted.
A3: No. | B3: Question | C3: Why it matters | D3: Default used for now | E3: Owner's answer
A4: Example | B4: Does the shop print labels? | C4: Would add a label template | D4: None | E4: Yes, shelf labels for loose items
A5: 1 | B5: Are 500ml and 1L bottles separate products or one product with pack sizes? | C5: Decides whether prices live on products or on a pack table | D5: Separate products
A6: 2 | B6: Does he buy from suppliers on credit? | C6: Decides if the supplier ledger is shown in the UI | D6: Supplier ledger tables exist but stay hidden
A7: 3 | B7: Does he track shop expenses and want a daily cash closing? | C7: Decides if expenses and cash closing screens are built | D7: Expenses table exists but stays hidden
A8: 4 | B8: Which details does he want on each farmer (father's name, CNIC, second phone, guarantor)? | C8: Adds optional columns to customers | D8: Only name, phone, village and notes
A9: 5 | B9: Does he use a barcode scanner? | C9: Barcode search in the POS | D9: Optional barcode column on products
A10: 6 | B10: Is the tax rate the same for everything or different per product? Do selling prices already include tax? | C10: Changes how line totals and tax are calculated | D10: Tax rate per product. Tax-inclusive pricing not decided
A11: 7 | B11: Should staff be allowed to void invoices? | C11: Voiding reverses a whole sale | D11: Owner only (recommended)
